Loading safetensors checkpoint shards:   0% Completed | 0/2 [00:00<?, ?it/s]
Loading safetensors checkpoint shards:  50% Completed | 1/2 [00:01<00:01,  1.26s/it]
Loading safetensors checkpoint shards: 100% Completed | 2/2 [00:04<00:00,  2.63s/it]
Loading safetensors checkpoint shards: 100% Completed | 2/2 [00:04<00:00,  2.42s/it]

Process SpawnProcess-1:
Traceback (most recent call last):
  File "/usr/lib/python3.12/multiprocessing/process.py", line 314, in _bootstrap
    self.run()
  File "/usr/lib/python3.12/multiprocessing/process.py", line 108, in run
    self._target(*self._args, **self._kwargs)
  File "/usr/local/lib/python3.12/dist-packages/vllm/engine/multiprocessing/engine.py", line 390, in run_mp_engine
    engine = MQLLMEngine.from_engine_args(engine_args=engine_args,
             ^^^^^^^^^^^^^^^^^^^^^^^^^^^^^^^^^^^^^^^^^^^^^^^^^^^^^
  File "/usr/local/lib/python3.12/dist-packages/vllm/engine/multiprocessing/engine.py", line 139, in from_engine_args
    return cls(
           ^^^^
  File "/usr/local/lib/python3.12/dist-packages/vllm/engine/multiprocessing/engine.py", line 78, in __init__
    self.engine = LLMEngine(*args, **kwargs)
                  ^^^^^^^^^^^^^^^^^^^^^^^^^^
  File "/usr/local/lib/python3.12/dist-packages/vllm/engine/llm_engine.py", line 348, in __init__
    self._initialize_kv_caches()
  File "/usr/local/lib/python3.12/dist-packages/vllm/engine/llm_engine.py", line 496, in _initialize_kv_caches
    self.model_executor.initialize_cache(num_gpu_blocks, num_cpu_blocks)
  File "/usr/local/lib/python3.12/dist-packages/vllm/executor/gpu_executor.py", line 129, in initialize_cache
    self.driver_worker.initialize_cache(num_gpu_blocks, num_cpu_blocks)
  File "/usr/local/lib/python3.12/dist-packages/vllm/worker/worker.py", line 296, in initialize_cache
    raise_if_cache_size_invalid(num_gpu_blocks,
  File "/usr/local/lib/python3.12/dist-packages/vllm/worker/worker.py", line 521, in raise_if_cache_size_invalid
    raise ValueError("No available memory for the cache blocks. "
ValueError: No available memory for the cache blocks. Try increasing `gpu_memory_utilization` when initializing the engine.
Traceback (most recent call last):
  File "<frozen runpy>", line 198, in _run_module_as_main
  File "<frozen runpy>", line 88, in _run_code
  File "/usr/local/lib/python3.12/dist-packages/vllm/entrypoints/openai/api_server.py", line 585, in <module>
    uvloop.run(run_server(args))
  File "/usr/local/lib/python3.12/dist-packages/uvloop/__init__.py", line 109, in run
    return __asyncio.run(
           ^^^^^^^^^^^^^^
  File "/usr/lib/python3.12/asyncio/runners.py", line 194, in run
    return runner.run(main)
           ^^^^^^^^^^^^^^^^
  File "/usr/lib/python3.12/asyncio/runners.py", line 118, in run
    return self._loop.run_until_complete(task)
           ^^^^^^^^^^^^^^^^^^^^^^^^^^^^^^^^^^^
  File "uvloop/loop.pyx", line 1518, in uvloop.loop.Loop.run_until_complete
  File "/usr/local/lib/python3.12/dist-packages/uvloop/__init__.py", line 61, in wrapper
    return await main
           ^^^^^^^^^^
  File "/usr/local/lib/python3.12/dist-packages/vllm/entrypoints/openai/api_server.py", line 552, in run_server
    async with build_async_engine_client(args) as engine_client:
               ^^^^^^^^^^^^^^^^^^^^^^^^^^^^^^^
  File "/usr/lib/python3.12/contextlib.py", line 210, in __aenter__
    return await anext(self.gen)
           ^^^^^^^^^^^^^^^^^^^^^
  File "/usr/local/lib/python3.12/dist-packages/vllm/entrypoints/openai/api_server.py", line 107, in build_async_engine_client
    async with build_async_engine_client_from_engine_args(
               ^^^^^^^^^^^^^^^^^^^^^^^^^^^^^^^^^^^^^^^^^^^
  File "/usr/lib/python3.12/contextlib.py", line 210, in __aenter__
    return await anext(self.gen)
           ^^^^^^^^^^^^^^^^^^^^^
  File "/usr/local/lib/python3.12/dist-packages/vllm/entrypoints/openai/api_server.py", line 194, in build_async_engine_client_from_engine_args
    raise RuntimeError(
RuntimeError: Engine process failed to start
